<?xml version="1.0"?>
<robot  xmlns:xacro="http://www.ros.org/wiki/xacro" name="mycobot_ai_no" >

  <xacro:property name="width" value=".2" />

  <link name="link1">
    <inertial>
    <origin xyz="0 0 0.1" rpy="0 0 0"/>
      <mass value="10"/>
      <inertia
        ixx="0.0" ixy="0.0" ixz="0.0"
        iyy="0.5" iyz="0.0"
        izz="0.0"/>
  </inertial>
    <visual>
      <geometry>
	     <!--- 0.0 0 -0.04  1.5708 3.14159-->
       <mesh filename="file://$(find gazebo_simulation_ros2)/urdf/joint1.dae"/>
      </geometry>
      <origin xyz = "0.0 0 0 " rpy = " 0 0 -1.5708"/>
    </visual>
    <collision>
      <geometry>
	     <!--- 0.0 0 -0.04  1.5708 3.14159-->
       <mesh filename="file://$(find gazebo_simulation_ros2)/urdf/joint1.dae"/>
        </geometry>
        <origin xyz = "0.0 0 0.0 " rpy = " 0 0 -1.5708"/>
    </collision>
  </link>

  <link name="link2">
    <inertial>
    <origin xyz="0 0 0.1" rpy="0 0 0"/>
      <mass value="0.2"/>
      <inertia
        ixx="0.0" ixy="0.0" ixz="0.0"
        iyy="0.5" iyz="0.0"
        izz="0.0"/>
    </inertial>
    <visual>
      <geometry>
       <mesh filename="file://$(find gazebo_simulation_ros2)/urdf/joint2.dae"/>
      </geometry>
      <origin xyz = "0.0 0 -0.061 " rpy = " 0 0 -1.5708"/>
    </visual>
    <collision>
     <geometry>
       <mesh filename="file://$(find gazebo_simulation_ros2)/urdf/joint2.dae"/>
      </geometry>
      <origin xyz = "0.0 0 -0.061 " rpy = " 0 0 -1.5708"/>
    </collision>
  </link>

  <link name="link3">
    <inertial>
    <origin xyz="0 0 0.1" rpy="0 0 0"/>
      <mass value="0.2"/>
      <inertia
        ixx="0.0" ixy="0.0" ixz="0.0"
        iyy="0.5" iyz="0.0"
        izz="0.0"/>
    </inertial>
    <visual>
      <geometry>
       <mesh filename="file://$(find gazebo_simulation_ros2)/urdf/joint3.dae"/>
      </geometry>
    <origin xyz = "0.0 0 0.03256 " rpy = " 0 -1.5708 0"/>
    </visual>
    <collision>
      <geometry>
       <mesh filename="file://$(find gazebo_simulation_ros2)/urdf/joint3.dae"/>
      </geometry>
      <origin xyz = "0.00 0 0.03256 " rpy = " 0 -1.5708 0"/>
    </collision>
  </link>

<link name="link4">
  <inertial>
    <origin xyz="0 0 0.1" rpy="0 0 0"/>
      <mass value="0.2"/>
      <inertia
        ixx="0.0" ixy="0.0" ixz="0.0"
        iyy="0.5" iyz="0.0"
        izz="0.0"/>
  </inertial>
    <visual>
      <geometry>
       <!--- 0.0 0 -0.04 -->
       <mesh filename="file://$(find gazebo_simulation_ros2)/urdf/joint4.dae"/>
      </geometry>
      <origin xyz = "0.0 0 0.03056 " rpy = " 0 -1.5708 0"/>
    </visual>
    <collision>
      <geometry>
       <!--- 0.0 0 -0.04 -->
       <mesh filename="file://$(find gazebo_simulation_ros2)/urdf/joint4.dae"/>
      </geometry>
      <origin xyz = "-0.0 0 0.03056 " rpy = " 0 -1.5708 0"/>
    </collision>
  </link>


  <link name="link5">
    <inertial>
    <origin xyz="0 0 0.1" rpy="0 0 0"/>
      <mass value="0.2"/>
      <inertia
        ixx="0.0" ixy="0.0" ixz="0.0"
        iyy="0.5" iyz="0.0"
        izz="0.0"/>
    </inertial>
    <visual>
      <geometry>
       <!--- 0.0 0 -0.04 -->
       <mesh filename="file://$(find gazebo_simulation_ros2)/urdf/joint5.dae"/>
      </geometry>
      <origin xyz = "0.0 0 -0.0340 " rpy = " -1.5708 0 0"/>
    </visual>
    <collision>
       <geometry>
       <!--- 0.0 0 -0.04 -->
       <mesh filename="file://$(find gazebo_simulation_ros2)/urdf/joint5.dae"/>
      </geometry>
      <origin xyz = "0.0 0 -0.0340 " rpy = " -1.5708 0 0"/>
    </collision>
  </link>


  <link name="link6">
    <inertial>
    <origin xyz="0 0 0.1" rpy="0 0 0"/>
      <mass value="0.2"/>
      <inertia
        ixx="0.0" ixy="0.0" ixz="0.0"
        iyy="0.5" iyz="0.0"
        izz="0.0"/>
    </inertial>
    <visual>
      <geometry>
       <!--- 0.0 0 -0.04 -->
       <mesh filename="file://$(find gazebo_simulation_ros2)/urdf/joint6.dae"/>
      </geometry>
    <origin xyz = "-0.00 0.0 -0.044 " rpy = " 0 0 0"/>
    </visual>
    <collision>
      <geometry>
       <!--- 0.0 0 -0.04 -->
       <mesh filename="file://$(find gazebo_simulation_ros2)/urdf/joint6.dae"/>
      </geometry>
    <origin xyz = "-0.00 0.0 -0.044 " rpy = " 0 0 0"/>
    </collision>
  </link>

  <link name="link6_flange">
    <inertial>
    <origin xyz="0 0 0.1" rpy="0 0 0"/>
      <mass value="0.1"/>
      <inertia
        ixx="0.0" ixy="0.0" ixz="0.0"
        iyy="0.0" iyz="0.0"
        izz="0.0"/>
    </inertial>
    <visual>
      <geometry>
       <!--- 0.0 0 -0.04 -->
       <box size="1 1 1"/>
       <mesh filename="file://$(find gazebo_simulation_ros2)/urdf/joint7.dae"/>
      </geometry>
    <origin xyz = "-0.00 0.00 -0.014 " rpy = " 0 0 0"/>
    </visual>
    <collision>
      <geometry>
       <!--- 0.0 0 -0.04 -->
       <mesh filename="file://$(find gazebo_simulation_ros2)/urdf/joint7.dae"/>
      </geometry>
    <origin xyz = "-0.00 0.00 -0.014 " rpy = " 0 0 0"/>
    </collision>
  </link>


  <joint name="joint1" type="revolute">
    <axis xyz="0 0 1"/>
    <limit effort = "1000.0" lower = "-3.14" upper = "3.14159" velocity = "1.0"/>
    <parent link="link1"/>
    <child link="link2"/>
    <origin xyz= "0 0 0.13156" rpy = "0 0 0"/>
  </joint>

    <joint name="joint2" type="revolute">
    <axis xyz="0 0 1"/>
    <limit effort = "1000.0" lower = "-3.14" upper = "3.14159" velocity = "1.0"/>
    <parent link="link2"/>
    <child link="link3"/>
    <origin xyz= "0 0 -0.001" rpy = "0 1.5708 -1.5708"/>
  </joint>

  <joint name="joint3" type="revolute">
    <axis xyz=" 0 0 1"/>
    <limit effort = "1000.0" lower = "-3.14" upper = "3.14159" velocity = "1.0"/>
    <parent link="link3"/>
    <child link="link4"/>
    <origin xyz= "  -0.1104 0 0   " rpy = "0 0 0"/>
  </joint>

  <joint name="joint4" type="revolute">
    <axis xyz=" 0 0 1"/>
    <limit effort = "1000.0" lower = "-3.14" upper = "3.14159" velocity = "1.0"/>
    <parent link="link4"/>
    <child link="link5"/>
    <origin xyz= "-0.096 0 0.06062" rpy = "0 0 -1.5708"/>
  </joint>

  <joint name="joint5" type="revolute">
    <axis xyz="0 0 1"/>
    <limit effort = "1000.0" lower = "-3.14" upper = "3.14159" velocity = "1.0"/>
    <parent link="link5"/>
    <child link="link6"/>
    <origin xyz= "0 -0.07318 0" rpy = "1.5708 -1.5708 0"/>
  </joint>

  <joint name="joint6" type="revolute">
    <axis xyz="0 0 1"/>
    <limit effort = "1000.0" lower = "-3.14" upper = "3.14159" velocity = "1.0"/>
    <parent link="link6"/>
    <child link="link6_flange"/>
    <origin xyz= "0 0.0486 -0.007" rpy = "-1.5708 0 0"/>
  </joint>


<link name="base_link"/>

<joint name="fixed" type="fixed">
  <parent link="base_link"/>
  <child link="link1"/>
</joint>

</robot>

